2021-01-11 07:15:43,244 DEBUG   MainThread:18640 [wandb_config.py:_load_defaults():154] no defaults not found in config-defaults.yaml
2021-01-11 07:15:48,271 DEBUG   MainThread:18640 [meta.py:_setup_code_git():49] probe for git information
2021-01-11 07:15:48,309 DEBUG   MainThread:18640 [run_manager.py:__init__():547] Initialized sync for ADR_prediction/382m3pok
2021-01-11 07:15:48,330 INFO    MainThread:18640 [run_manager.py:wrap_existing_process():1149] wrapping existing process 18628
2021-01-11 07:15:48,331 WARNING MainThread:18640 [io_wrap.py:register():108] SIGWINCH handler was not None: <Handlers.SIG_DFL: 0>
2021-01-11 07:15:49,261 INFO    Thread-4  :18640 [run_manager.py:_on_file_created():681] file/dir created: /workspace/DeepCE/DeepCE/adr_prediction/wandb/run-20210111_071537-382m3pok/wandb-metadata.json
2021-01-11 07:15:58,397 INFO    MainThread:18640 [run_manager.py:init_run():928] system metrics and metadata threads started
2021-01-11 07:15:58,397 INFO    MainThread:18640 [run_manager.py:init_run():967] upserting run before process can begin, waiting at most 10 seconds
2021-01-11 07:16:08,399 ERROR   MainThread:18640 [run_manager.py:init_run():972] Failed to connect to W&B servers after 10 seconds.                    Letting user process proceed while attempting to reconnect.
2021-01-11 07:16:08,399 INFO    MainThread:18640 [run_manager.py:wrap_existing_process():1166] informing user process we are ready to proceed
2021-01-11 07:16:08,408 INFO    MainThread:18640 [run_manager.py:_sync_etc():1298] entering loop for messages from user process
2021-01-11 07:16:20,447 ERROR   Thread-16 :18640 [retry.py:__call__():108] Retry attempt failed:
Traceback (most recent call last):
  File "/opt/conda/envs/drug_combine/lib/python3.7/site-packages/urllib3/connectionpool.py", line 421, in _make_request
    six.raise_from(e, None)
  File "<string>", line 3, in raise_from
  File "/opt/conda/envs/drug_combine/lib/python3.7/site-packages/urllib3/connectionpool.py", line 416, in _make_request
    httplib_response = conn.getresponse()
  File "/opt/conda/envs/drug_combine/lib/python3.7/http/client.py", line 1344, in getresponse
    response.begin()
  File "/opt/conda/envs/drug_combine/lib/python3.7/http/client.py", line 306, in begin
    version, status, reason = self._read_status()
  File "/opt/conda/envs/drug_combine/lib/python3.7/http/client.py", line 267, in _read_status
    line = str(self.fp.readline(_MAXLINE + 1), "iso-8859-1")
  File "/opt/conda/envs/drug_combine/lib/python3.7/socket.py", line 589, in readinto
    return self._sock.recv_into(b)
  File "/opt/conda/envs/drug_combine/lib/python3.7/site-packages/urllib3/contrib/pyopenssl.py", line 326, in recv_into
    raise timeout("The read operation timed out")
socket.timeout: The read operation timed out

During handling of the above exception, another exception occurred:

Traceback (most recent call last):
  File "/opt/conda/envs/drug_combine/lib/python3.7/site-packages/requests/adapters.py", line 449, in send
    timeout=timeout
  File "/opt/conda/envs/drug_combine/lib/python3.7/site-packages/urllib3/connectionpool.py", line 720, in urlopen
    method, url, error=e, _pool=self, _stacktrace=sys.exc_info()[2]
  File "/opt/conda/envs/drug_combine/lib/python3.7/site-packages/urllib3/util/retry.py", line 400, in increment
    raise six.reraise(type(error), error, _stacktrace)
  File "/opt/conda/envs/drug_combine/lib/python3.7/site-packages/urllib3/packages/six.py", line 735, in reraise
    raise value
  File "/opt/conda/envs/drug_combine/lib/python3.7/site-packages/urllib3/connectionpool.py", line 672, in urlopen
    chunked=chunked,
  File "/opt/conda/envs/drug_combine/lib/python3.7/site-packages/urllib3/connectionpool.py", line 423, in _make_request
    self._raise_timeout(err=e, url=url, timeout_value=read_timeout)
  File "/opt/conda/envs/drug_combine/lib/python3.7/site-packages/urllib3/connectionpool.py", line 331, in _raise_timeout
    self, url, "Read timed out. (read timeout=%s)" % timeout_value
urllib3.exceptions.ReadTimeoutError: HTTPSConnectionPool(host='api.wandb.ai', port=443): Read timed out. (read timeout=10)

During handling of the above exception, another exception occurred:

Traceback (most recent call last):
  File "/opt/conda/envs/drug_combine/lib/python3.7/site-packages/wandb/retry.py", line 95, in __call__
    result = self._call_fn(*args, **kwargs)
  File "/opt/conda/envs/drug_combine/lib/python3.7/site-packages/wandb/apis/internal.py", line 108, in execute
    return self.client.execute(*args, **kwargs)
  File "/opt/conda/envs/drug_combine/lib/python3.7/site-packages/gql/client.py", line 52, in execute
    result = self._get_result(document, *args, **kwargs)
  File "/opt/conda/envs/drug_combine/lib/python3.7/site-packages/gql/client.py", line 60, in _get_result
    return self.transport.execute(document, *args, **kwargs)
  File "/opt/conda/envs/drug_combine/lib/python3.7/site-packages/gql/transport/requests.py", line 38, in execute
    request = requests.post(self.url, **post_args)
  File "/opt/conda/envs/drug_combine/lib/python3.7/site-packages/requests/api.py", line 119, in post
    return request('post', url, data=data, json=json, **kwargs)
  File "/opt/conda/envs/drug_combine/lib/python3.7/site-packages/requests/api.py", line 61, in request
    return session.request(method=method, url=url, **kwargs)
  File "/opt/conda/envs/drug_combine/lib/python3.7/site-packages/requests/sessions.py", line 530, in request
    resp = self.send(prep, **send_kwargs)
  File "/opt/conda/envs/drug_combine/lib/python3.7/site-packages/requests/sessions.py", line 643, in send
    r = adapter.send(request, **kwargs)
  File "/opt/conda/envs/drug_combine/lib/python3.7/site-packages/requests/adapters.py", line 529, in send
    raise ReadTimeout(e, request=request)
requests.exceptions.ReadTimeout: HTTPSConnectionPool(host='api.wandb.ai', port=443): Read timed out. (read timeout=10)
2021-01-11 07:16:28,001 INFO    MainThread:18640 [run_manager.py:_sync_etc():1355] process received interrupt signal, shutting down
2021-01-11 07:16:28,001 INFO    MainThread:18640 [run_manager.py:_sync_etc():1408] closing log streams and sending exitcode to W&B
2021-01-11 07:16:28,002 INFO    MainThread:18640 [run_manager.py:shutdown():1072] shutting down system stats and metadata service
s/urllib3/connectionpool.py", line 416, in _make_request
    httplib_response = conn.getresponse()
  File "/opt/conda/envs/drug_combine/lib/python3.7/http/client.py", line 1344, in getresponse
    response.begin()
  File "/opt/conda/envs/drug_combine/lib/python3.7/http/client.py", line 306, in begin
    version, status, reason = self._read_status()
  File "/opt/conda/envs/drug_combine/lib/python3.7/http/client.py", line 267, in _read_status
    line = str(self.fp.readline(_MAXLINE + 1), "iso-8859-1")
  File "/opt/conda/envs/drug_combine/lib/python3.7/socket.py", line 589, in readinto
    return self._sock.recv_into(b)
  File "/opt/conda/envs/drug_combine/lib/python3.7/site-packages/urllib3/contrib/pyopenssl.py", line 326, in recv_into
    raise timeout("The read operation timed out")
socket.timeout: The read operation timed out

During handling of the above exception, another exception occurred:

Traceback (most recent call last):
  File "/opt/conda/envs/drug_combine/lib/python3.7/site-packages/requests/adapters.py", line 449, in send
    timeout=timeout
  File "/opt/conda/envs/drug_combine/lib/python3.7/site-packages/urllib3/connectionpool.py", line 720, in urlopen
    method, url, error=e, _pool=self, _stacktrace=sys.exc_info()[2]
  File "/opt/conda/envs/drug_combine/lib/python3.7/site-packages/urllib3/util/retry.py", line 400, in increment
    raise six.reraise(type(error), error, _stacktrace)
  File "/opt/conda/envs/drug_combine/lib/python3.7/site-packages/urllib3/packages/six.py", line 735, in reraise
    raise value
  File "/opt/conda/envs/drug_combine/lib/python3.7/site-packages/urllib3/connectionpool.py", line 672, in urlopen
    chunked=chunked,
  File "/opt/conda/envs/drug_combine/lib/python3.7/site-packages/urllib3/connectionpool.py", line 423, in _make_request
    self._raise_timeout(err=e, url=url, timeout_value=read_timeout)
  File "/opt/conda/envs/drug_combine/lib/python3.7/site-packages/urllib3/connectionpool.py", line 331, in _raise_timeout
    self, url, "Read timed out. (read timeout=%s)" % timeout_value
urllib3.exceptions.ReadTimeoutError: HTTPSConnectionPool(host='api.wandb.ai', port=443): Read timed out. (read timeout=10)

During handling of the above exception, another exception occurred:

Traceback (most recent call last):
  File "/opt/conda/envs/drug_combine/lib/python3.7/site-packages/wandb/retry.py", line 95, in __call__
    result = self._call_fn(*args, **kwargs)
  File "/opt/conda/envs/drug_combine/lib/python3.7/site-packages/wandb/apis/internal.py", line 108, in execute
    return self.client.execute(*args, **kwargs)
  File "/opt/conda/envs/drug_combine/lib/python3.7/site-packages/gql/client.py", line 52, in execute
    result = self._get_result(document, *args, **kwargs)
  File "/opt/conda/envs/drug_combine/lib/python3.7/site-packages/gql/client.py", line 60, in _get_result
    return self.transport.execute(document, *args, **kwargs)
  File "/opt/conda/envs/drug_combine/lib/python3.7/site-packages/gql/transport/requests.py", line 38, in execute
    request = requests.post(self.url, **post_args)
  File "/opt/conda/envs/drug_combine/lib/python3.7/site-packages/requests/api.py", line 119, in post
    return request('post', url, data=data, json=json, **kwargs)
  File "/opt/conda/envs/drug_combine/lib/python3.7/site-packages/requests/api.py", line 61, in request
    return session.request(method=method, url=url, **kwargs)
  File "/opt/conda/envs/drug_combine/lib/python3.7/site-packages/requests/sessions.py", line 530, in request
    resp = self.send(prep, **send_kwargs)
  File "/opt/conda/envs/drug_combine/lib/python3.7/site-packages/requests/sessions.py", line 643, in send
    r = adapter.send(request, **kwargs)
  File "/opt/conda/envs/drug_combine/lib/python3.7/site-packages/requests/adapters.py", line 529, in send
    raise ReadTimeout(e, request=request)
requests.exceptions.ReadTimeout: HTTPSConnectionPool(host='api.wandb.ai', port=443): Read timed out. (read timeout=10)
2021-01-11 07:16:28,001 INFO    MainThread:18640 [382m3pok:run_manager.py:_sync_etc():1355] process received interrupt signal, shutting down
2021-01-11 07:16:28,001 INFO    MainThread:18640 [382m3pok:run_manager.py:_sync_etc():1408] closing log streams and sending exitcode to W&B
2021-01-11 07:16:28,002 INFO    MainThread:18640 [382m3pok:run_manager.py:shutdown():1072] shutting down system stats and metadata service
