Use GPU if it is deep model: True
Retry attempt failed:
Traceback (most recent call last):
  File "/opt/conda/envs/drug_combine/lib/python3.7/site-packages/urllib3/connectionpool.py", line 421, in _make_request
    six.raise_from(e, None)
  File "<string>", line 3, in raise_from
  File "/opt/conda/envs/drug_combine/lib/python3.7/site-packages/urllib3/connectionpool.py", line 416, in _make_request
    httplib_response = conn.getresponse()
  File "/opt/conda/envs/drug_combine/lib/python3.7/http/client.py", line 1344, in getresponse
    response.begin()
  File "/opt/conda/envs/drug_combine/lib/python3.7/http/client.py", line 306, in begin
    version, status, reason = self._read_status()
  File "/opt/conda/envs/drug_combine/lib/python3.7/http/client.py", line 267, in _read_status
    line = str(self.fp.readline(_MAXLINE + 1), "iso-8859-1")
  File "/opt/conda/envs/drug_combine/lib/python3.7/socket.py", line 589, in readinto
    return self._sock.recv_into(b)
  File "/opt/conda/envs/drug_combine/lib/python3.7/site-packages/urllib3/contrib/pyopenssl.py", line 326, in recv_into
    raise timeout("The read operation timed out")
socket.timeout: The read operation timed out

During handling of the above exception, another exception occurred:

Traceback (most recent call last):
  File "/opt/conda/envs/drug_combine/lib/python3.7/site-packages/requests/adapters.py", line 449, in send
    timeout=timeout
  File "/opt/conda/envs/drug_combine/lib/python3.7/site-packages/urllib3/connectionpool.py", line 720, in urlopen
    method, url, error=e, _pool=self, _stacktrace=sys.exc_info()[2]
  File "/opt/conda/envs/drug_combine/lib/python3.7/site-packages/urllib3/util/retry.py", line 400, in increment
    raise six.reraise(type(error), error, _stacktrace)
  File "/opt/conda/envs/drug_combine/lib/python3.7/site-packages/urllib3/packages/six.py", line 735, in reraise
    raise value
  File "/opt/conda/envs/drug_combine/lib/python3.7/site-packages/urllib3/connectionpool.py", line 672, in urlopen
    chunked=chunked,
  File "/opt/conda/envs/drug_combine/lib/python3.7/site-packages/urllib3/connectionpool.py", line 423, in _make_request
    self._raise_timeout(err=e, url=url, timeout_value=read_timeout)
  File "/opt/conda/envs/drug_combine/lib/python3.7/site-packages/urllib3/connectionpool.py", line 331, in _raise_timeout
    self, url, "Read timed out. (read timeout=%s)" % timeout_value
urllib3.exceptions.ReadTimeoutError: HTTPSConnectionPool(host='api.wandb.ai', port=443): Read timed out. (read timeout=10)

During handling of the above exception, another exception occurred:

Traceback (most recent call last):
  File "/opt/conda/envs/drug_combine/lib/python3.7/site-packages/wandb/retry.py", line 95, in __call__
    result = self._call_fn(*args, **kwargs)
  File "/opt/conda/envs/drug_combine/lib/python3.7/site-packages/wandb/apis/internal.py", line 108, in execute
    return self.client.execute(*args, **kwargs)
  File "/opt/conda/envs/drug_combine/lib/python3.7/site-packages/gql/client.py", line 52, in execute
    result = self._get_result(document, *args, **kwargs)
  File "/opt/conda/envs/drug_combine/lib/python3.7/site-packages/gql/client.py", line 60, in _get_result
    return self.transport.execute(document, *args, **kwargs)
  File "/opt/conda/envs/drug_combine/lib/python3.7/site-packages/gql/transport/requests.py", line 38, in execute
    request = requests.post(self.url, **post_args)
  File "/opt/conda/envs/drug_combine/lib/python3.7/site-packages/requests/api.py", line 119, in post
    return request('post', url, data=data, json=json, **kwargs)
  File "/opt/conda/envs/drug_combine/lib/python3.7/site-packages/requests/api.py", line 61, in request
    return session.request(method=method, url=url, **kwargs)
  File "/opt/conda/envs/drug_combine/lib/python3.7/site-packages/requests/sessions.py", line 530, in request
    resp = self.send(prep, **send_kwargs)
  File "/opt/conda/envs/drug_combine/lib/python3.7/site-packages/requests/sessions.py", line 643, in send
    r = adapter.send(request, **kwargs)
  File "/opt/conda/envs/drug_combine/lib/python3.7/site-packages/requests/adapters.py", line 529, in send
    raise ReadTimeout(e, request=request)
requests.exceptions.ReadTimeout: HTTPSConnectionPool(host='api.wandb.ai', port=443): Read timed out. (read timeout=10)
[34m[1mwandb[0m: Network error (ReadTimeout), entering retry loop. See /workspace/DeepCE/DeepCE/adr_prediction/wandb/debug.log for full traceback.
